Workbook

Sheet Dashboard
B1: Arabian Horse Scoring & Bloodline Dashboard
B2: 40 horses · 3 judges · 6 AHA-style halter categories (0–20) · synthetic practice data — not official AHA results
B4: Horses | E4: Avg total score | H4: Elite horses | K4: Top sire line | N4: Herd weakest trait | Q4: Avg judge spread
B5: =COUNTA(Horse_Summary!$A$2:$A$41) -> 40 | E5: =AVERAGE(Horse_Summary!$O$2:$O$41) -> 109.8425 | H5: =COUNTIF(Horse_Summary!$S$2:$S$41,"Elite") -> 11 | K5: =INDEX(Bloodline_Analysis!$A$6:$A$10,MATCH(1,Bloodline_Analysis!$M$6:$M$10,0)) -> Pogrom | N5: =INDEX(Conformation!$A$5:$A$10,MATCH(MIN(Conformation!$B$5:$B$10),Conformation!$B$5:$B$10,0)) -> Legs | Q5: =AVERAGE(Horse_Summary!$P$2:$P$41) -> 4.51
B8: Top 10 horses | L8: Sire lines at a glance
B9: # | C9: Horse | E9: Sire | G9: Sex | H9: Age group | I9: Avg total | J9: Tier | L9: Sire | N9: Horses | O9: Avg total | P9: Elite % | Q9: Best trait | R9: Weakest trait
B10: 1 | C10: =INDEX(Horse_Summary!$B$2:$B$41,MATCH(1,Horse_Summary!$R$2:$R$41,0)) -> HA Rami Royal Flame | E10: =INDEX(Horse_Summary!$C$2:$C$41,MATCH(1,Horse_Summary!$R$2:$R$41,0)) -> Pogrom | G10: =INDEX(Horse_Summary!$E$2:$E$41,MATCH(1,Horse_Summary!$R$2:$R$41,0)) -> Stallion | H10: =INDEX(Horse_Summary!$F$2:$F$41,MATCH(1,Horse_Summary!$R$2:$R$41,0)) -> Mature | I10: =INDEX(Horse_Summary!$O$2:$O$41,MATCH(1,Horse_Summary!$R$2:$R$41,0)) -> 114.33333 | J10: =INDEX(Horse_Summary!$S$2:$S$41,MATCH(1,Horse_Summary!$R$2:$R$41,0)) -> Elite | L10: =Bloodline_Analysis!A6 -> Pogrom | N10: =Bloodline_Analysis!C6 -> 10 | O10: =Bloodline_Analysis!D6 -> 112.30667 | P10: =Bloodline_Analysis!I6 -> 0.5 | Q10: =Bloodline_Analysis!H15 -> Movement | R10: =Bloodline_Analysis!I15 -> Head_Neck
B11: 2 | C11: =INDEX(Horse_Summary!$B$2:$B$41,MATCH(2,Horse_Summary!$R$2:$R$41,0)) -> HA Kairo Marquis | E11: =INDEX(Horse_Summary!$C$2:$C$41,MATCH(2,Horse_Summary!$R$2:$R$41,0)) -> Pogrom | G11: =INDEX(Horse_Summary!$E$2:$E$41,MATCH(2,Horse_Summary!$R$2:$R$41,0)) -> Filly | H11: =INDEX(Horse_Summary!$F$2:$F$41,MATCH(2,Horse_Summary!$R$2:$R$41,0)) -> Young Horse | I11: =INDEX(Horse_Summary!$O$2:$O$41,MATCH(2,Horse_Summary!$R$2:$R$41,0)) -> 113.93333 | J11: =INDEX(Horse_Summary!$S$2:$S$41,MATCH(2,Horse_Summary!$R$2:$R$41,0)) -> Elite | L11: =Bloodline_Analysis!A7 -> Cavali by Da Valentio | N11: =Bloodline_Analysis!C7 -> 7 | O11: =Bloodline_Analysis!D7 -> 112.14762 | P11: =Bloodline_Analysis!I7 -> 0.85714286 | Q11: =Bloodline_Analysis!H16 -> Type | R11: =Bloodline_Analysis!I16 -> Body_Topline
B12: 3 | C12: =INDEX(Horse_Summary!$B$2:$B$41,MATCH(3,Horse_Summary!$R$2:$R$41,0)) -> HA Rayan Dream | E12: =INDEX(Horse_Summary!$C$2:$C$41,MATCH(3,Horse_Summary!$R$2:$R$41,0)) -> Pogrom | G12: =INDEX(Horse_Summary!$E$2:$E$41,MATCH(3,Horse_Summary!$R$2:$R$41,0)) -> Colt | H12: =INDEX(Horse_Summary!$F$2:$F$41,MATCH(3,Horse_Summary!$R$2:$R$41,0)) -> Junior | I12: =INDEX(Horse_Summary!$O$2:$O$41,MATCH(3,Horse_Summary!$R$2:$R$41,0)) -> 113.86667 | J12: =INDEX(Horse_Summary!$S$2:$S$41,MATCH(3,Horse_Summary!$R$2:$R$41,0)) -> Elite | L12: =Bloodline_Analysis!A8 -> Abha Qatar | N12: =Bloodline_Analysis!C8 -> 8 | O12: =Bloodline_Analysis!D8 -> 108.95417 | P12: =Bloodline_Analysis!I8 -> 0 | Q12: =Bloodline_Analysis!H17 -> Head_Neck | R12: =Bloodline_Analysis!I17 -> Body_Topline
B13: 4 | C13: =INDEX(Horse_Summary!$B$2:$B$41,MATCH(4,Horse_Summary!$R$2:$R$41,0)) -> HA Amira Legacy | E13: =INDEX(Horse_Summary!$C$2:$C$41,MATCH(4,Horse_Summary!$R$2:$R$41,0)) -> Pogrom | G13: =INDEX(Horse_Summary!$E$2:$E$41,MATCH(4,Horse_Summary!$R$2:$R$41,0)) -> Gelding | H13: =INDEX(Horse_Summary!$F$2:$F$41,MATCH(4,Horse_Summary!$R$2:$R$41,0)) -> Young Horse | I13: =INDEX(Horse_Summary!$O$2:$O$41,MATCH(4,Horse_Summary!$R$2:$R$41,0)) -> 113.43333 | J13: =INDEX(Horse_Summary!$S$2:$S$41,MATCH(4,Horse_Summary!$R$2:$R$41,0)) -> Elite | L13: =Bloodline_Analysis!A9 -> Van Gogh AM | N13: =Bloodline_Analysis!C9 -> 8 | O13: =Bloodline_Analysis!D9 -> 108.90417 | P13: =Bloodline_Analysis!I9 -> 0 | Q13: =Bloodline_Analysis!H18 -> Head_Neck | R13: =Bloodline_Analysis!I18 -> Legs
B14: 5 | C14: =INDEX(Horse_Summary!$B$2:$B$41,MATCH(5,Horse_Summary!$R$2:$R$41,0)) -> HA Rahma Al Jannat | E14: =INDEX(Horse_Summary!$C$2:$C$41,MATCH(5,Horse_Summary!$R$2:$R$41,0)) -> Pogrom | G14: =INDEX(Horse_Summary!$E$2:$E$41,MATCH(5,Horse_Summary!$R$2:$R$41,0)) -> Gelding | H14: =INDEX(Horse_Summary!$F$2:$F$41,MATCH(5,Horse_Summary!$R$2:$R$41,0)) -> Mature | I14: =INDEX(Horse_Summary!$O$2:$O$41,MATCH(5,Horse_Summary!$R$2:$R$41,0)) -> 112.93333 | J14: =INDEX(Horse_Summary!$S$2:$S$41,MATCH(5,Horse_Summary!$R$2:$R$41,0)) -> Elite | L14: =Bloodline_Analysis!A10 -> Titan AS | N14: =Bloodline_Analysis!C10 -> 7 | O14: =Bloodline_Analysis!D10 -> 106.10476 | P14: =Bloodline_Analysis!I10 -> 0 | Q14: =Bloodline_Analysis!H19 -> Body_Topline | R14: =Bloodline_Analysis!I19 -> Head_Neck
B15: 6 | C15: =INDEX(Horse_Summary!$B$2:$B$41,MATCH(6,Horse_Summary!$R$2:$R$41,0)) -> HA Rashid Golden Star | E15: =INDEX(Horse_Summary!$C$2:$C$41,MATCH(6,Horse_Summary!$R$2:$R$41,0)) -> Cavali by Da Valentio | G15: =INDEX(Horse_Summary!$E$2:$E$41,MATCH(6,Horse_Summary!$R$2:$R$41,0)) -> Colt | H15: =INDEX(Horse_Summary!$F$2:$F$41,MATCH(6,Horse_Summary!$R$2:$R$41,0)) -> Mature | I15: =INDEX(Horse_Summary!$O$2:$O$41,MATCH(6,Horse_Summary!$R$2:$R$41,0)) -> 112.8 | J15: =INDEX(Horse_Summary!$S$2:$S$41,MATCH(6,Horse_Summary!$R$2:$R$41,0)) -> Elite
B16: 7 | C16: =INDEX(Horse_Summary!$B$2:$B$41,MATCH(7,Horse_Summary!$R$2:$R$41,0)) -> HA Mira Valentino | E16: =INDEX(Horse_Summary!$C$2:$C$41,MATCH(7,Horse_Summary!$R$2:$R$41,0)) -> Cavali by Da Valentio | G16: =INDEX(Horse_Summary!$E$2:$E$41,MATCH(7,Horse_Summary!$R$2:$R$41,0)) -> Colt | H16: =INDEX(Horse_Summary!$F$2:$F$41,MATCH(7,Horse_Summary!$R$2:$R$41,0)) -> Mature | I16: =INDEX(Horse_Summary!$O$2:$O$41,MATCH(7,Horse_Summary!$R$2:$R$41,0)) -> 112.73333 | J16: =INDEX(Horse_Summary!$S$2:$S$41,MATCH(7,Horse_Summary!$R$2:$R$41,0)) -> Elite
B17: 8 | C17: =INDEX(Horse_Summary!$B$2:$B$41,MATCH(8,Horse_Summary!$R$2:$R$41,0)) -> HA Noura Al Jannat | E17: =INDEX(Horse_Summary!$C$2:$C$41,MATCH(8,Horse_Summary!$R$2:$R$41,0)) -> Cavali by Da Valentio | G17: =INDEX(Horse_Summary!$E$2:$E$41,MATCH(8,Horse_Summary!$R$2:$R$41,0)) -> Colt | H17: =INDEX(Horse_Summary!$F$2:$F$41,MATCH(8,Horse_Summary!$R$2:$R$41,0)) -> Young Horse | I17: =INDEX(Horse_Summary!$O$2:$O$41,MATCH(8,Horse_Summary!$R$2:$R$41,0)) -> 112.46667 | J17: =INDEX(Horse_Summary!$S$2:$S$41,MATCH(8,Horse_Summary!$R$2:$R$41,0)) -> Elite | L17: Horse lookup — pick a horse from the yellow cell
B18: 9 | C18: =INDEX(Horse_Summary!$B$2:$B$41,MATCH(9,Horse_Summary!$R$2:$R$41,0)) -> HA Layla Dream | E18: =INDEX(Horse_Summary!$C$2:$C$41,MATCH(9,Horse_Summary!$R$2:$R$41,0)) -> Cavali by Da Valentio | G18: =INDEX(Horse_Summary!$E$2:$E$41,MATCH(9,Horse_Summary!$R$2:$R$41,0)) -> Mare | H18: =INDEX(Horse_Summary!$F$2:$F$41,MATCH(9,Horse_Summary!$R$2:$R$41,0)) -> Young Horse | I18: =INDEX(Horse_Summary!$O$2:$O$41,MATCH(9,Horse_Summary!$R$2:$R$41,0)) -> 112.13333 | J18: =INDEX(Horse_Summary!$S$2:$S$41,MATCH(9,Horse_Summary!$R$2:$R$41,0)) -> Elite | L18: Horse: | M18: HA Amira Legacy
B19: 10 | C19: =INDEX(Horse_Summary!$B$2:$B$41,MATCH(10,Horse_Summary!$R$2:$R$41,0)) -> HA Nashira Royal Flame | E19: =INDEX(Horse_Summary!$C$2:$C$41,MATCH(10,Horse_Summary!$R$2:$R$41,0)) -> Cavali by Da Valentio | G19: =INDEX(Horse_Summary!$E$2:$E$41,MATCH(10,Horse_Summary!$R$2:$R$41,0)) -> Colt | H19: =INDEX(Horse_Summary!$F$2:$F$41,MATCH(10,Horse_Summary!$R$2:$R$41,0)) -> Mature | I19: =INDEX(Horse_Summary!$O$2:$O$41,MATCH(10,Horse_Summary!$R$2:$R$41,0)) -> 112.13333 | J19: =INDEX(Horse_Summary!$S$2:$S$41,MATCH(10,Horse_Summary!$R$2:$R$41,0)) -> Elite | L19: Sire | M19: =INDEX(Horse_Summary!$C$2:$C$41,MATCH($M$18,Horse_Summary!$B$2:$B$41,0)) -> Pogrom | O19: Rank | P19: =INDEX(Horse_Summary!$Q$2:$Q$41,MATCH($M$18,Horse_Summary!$B$2:$B$41,0)) -> 4
L20: Dam sire | M20: =INDEX(Horse_Summary!$D$2:$D$41,MATCH($M$18,Horse_Summary!$B$2:$B$41,0)) -> El Nabila B | O20: Tier | P20: =INDEX(Horse_Summary!$S$2:$S$41,MATCH($M$18,Horse_Summary!$B$2:$B$41,0)) -> Elite
L21: Sex | M21: =INDEX(Horse_Summary!$E$2:$E$41,MATCH($M$18,Horse_Summary!$B$2:$B$41,0)) -> Gelding | O21: Strongest | P21: =INDEX(Horse_Summary!$T$2:$T$41,MATCH($M$18,Horse_Summary!$B$2:$B$41,0)) -> Balance
L22: Age group | M22: =INDEX(Horse_Summary!$F$2:$F$41,MATCH($M$18,Horse_Summary!$B$2:$B$41,0)) -> Young Horse | O22: Focus area | P22: =INDEX(Horse_Summary!$U$2:$U$41,MATCH($M$18,Horse_Summary!$B$2:$B$41,0)) -> Legs
L23: Avg total | M23: =INDEX(Horse_Summary!$O$2:$O$41,MATCH($M$18,Horse_Summary!$B$2:$B$41,0)) -> 113.43333 | O23: Judge spread | P23: =INDEX(Horse_Summary!$P$2:$P$41,MATCH($M$18,Horse_Summary!$B$2:$B$41,0)) -> 1.8
L25: Trait | M25: Horse | N25: Herd avg | O25: Sire avg | P25: Vs herd
L26: Type | M26: =INDEX(Horse_Summary!$I$2:$I$41,MATCH($M$18,Horse_Summary!$B$2:$B$41,0)) -> 18.533333 | N26: =AVERAGE(Horse_Summary!$I$2:$I$41) -> 18.44 | O26: =AVERAGEIF(Horse_Summary!$C$2:$C$41,INDEX(Horse_Summary!$C$2:$C$41,MATCH($M$18,Horse_Summary!$B$2:$B$41,0)),Horse_Summary!$I$2:$I$41) -> 18.843333 | P26: =M26-N26 -> 0.093333333
L27: Head_Neck | M27: =INDEX(Horse_Summary!$J$2:$J$41,MATCH($M$18,Horse_Summary!$B$2:$B$41,0)) -> 19.033333 | N27: =AVERAGE(Horse_Summary!$J$2:$J$41) -> 18.355 | O27: =AVERAGEIF(Horse_Summary!$C$2:$C$41,INDEX(Horse_Summary!$C$2:$C$41,MATCH($M$18,Horse_Summary!$B$2:$B$41,0)),Horse_Summary!$J$2:$J$41) -> 18.293333 | P27: =M27-N27 -> 0.67833333
L28: Body_Topline | M28: =INDEX(Horse_Summary!$K$2:$K$41,MATCH($M$18,Horse_Summary!$B$2:$B$41,0)) -> 19.1 | N28: =AVERAGE(Horse_Summary!$K$2:$K$41) -> 18.301667 | O28: =AVERAGEIF(Horse_Summary!$C$2:$C$41,INDEX(Horse_Summary!$C$2:$C$41,MATCH($M$18,Horse_Summary!$B$2:$B$41,0)),Horse_Summary!$K$2:$K$41) -> 19.003333 | P28: =M28-N28 -> 0.79833333
L29: Legs | M29: =INDEX(Horse_Summary!$L$2:$L$41,MATCH($M$18,Horse_Summary!$B$2:$B$41,0)) -> 18.033333 | N29: =AVERAGE(Horse_Summary!$L$2:$L$41) -> 18.125 | O29: =AVERAGEIF(Horse_Summary!$C$2:$C$41,INDEX(Horse_Summary!$C$2:$C$41,MATCH($M$18,Horse_Summary!$B$2:$B$41,0)),Horse_Summary!$L$2:$L$41) -> 18.453333 | P29: =M29-N29 -> -0.091666667
L30: Movement | M30: =INDEX(Horse_Summary!$M$2:$M$41,MATCH($M$18,Horse_Summary!$B$2:$B$41,0)) -> 18.933333 | N30: =AVERAGE(Horse_Summary!$M$2:$M$41) -> 18.33 | O30: =AVERAGEIF(Horse_Summary!$C$2:$C$41,INDEX(Horse_Summary!$C$2:$C$41,MATCH($M$18,Horse_Summary!$B$2:$B$41,0)),Horse_Summary!$M$2:$M$41) -> 19.206667 | P30: =M30-N30 -> 0.60333333
L31: Balance | M31: =INDEX(Horse_Summary!$N$2:$N$41,MATCH($M$18,Horse_Summary!$B$2:$B$41,0)) -> 19.8 | N31: =AVERAGE(Horse_Summary!$N$2:$N$41) -> 18.290833 | O31: =AVERAGEIF(Horse_Summary!$C$2:$C$41,INDEX(Horse_Summary!$C$2:$C$41,MATCH($M$18,Horse_Summary!$B$2:$B$41,0)),Horse_Summary!$N$2:$N$41) -> 18.506667 | P31: =M31-N31 -> 1.5091667

Sheet About
A1: About this workbook
A3: Project | B3: Horse Scoring & Bloodline Analytics — Excel component
A4: Data | B4: Synthetic practice dataset: 40 Arabian horses, 120 judge score rows (3 judges x 40), 15 parent records. Only sire names are real; all scores and pedigrees are hypothetical.
A5: Scoring | B5: Six AHA-style halter categories (Type, Head/Neck, Body/Topline, Legs, Movement, Balance), 0–20 each, total out of 120 per judge. Horse score = average of the 3 judges.
A7: Sheet guide
A8: Dashboard | B8: KPIs, Top 10, sire summary, interactive horse lookup (yellow dropdown) and charts.
A9: Horse_Profile | B9: Source profiles + computed Age and a sex/age data-quality flag.
A10: Judge_Scores | B10: Source judge scores; TotalScore = SUM of the six traits.
A11: Parent_Reference | B11: Sire / dam-sire reference + offspring count, average and gap vs parent score.
A12: Horse_Summary | B12: One row per horse: trait averages, total, rank, tier, strength/focus, parent scores. Feeds all analysis sheets.
A13: Bloodline_Analysis | B13: Sire line, dam sire, dam line and farm group comparisons; trait profile per sire.
A14: Parent_Performance | B14: Correlation / slope of parent show scores vs offspring scores.
A15: Age_Sex | B15: Age group x sex matrices for score, count and traits.
A16: Conformation | B16: Herd trait averages, strongest/weakest counts, below-threshold counts, trait correlations.
A17: Judge_Analysis | B17: Judge bias by trait and inter-judge agreement.
A18: Settings | B18: Inputs: reference year, tier cut-offs, colt/filly age limit.
A20: Colour legend | B20: Blue text on yellow = input you can change · Black = formula · Green = link to another sheet · Blue/red cell shading = above/below average.
A21: Formulas | B21: Every analysis number is a live formula; edit Judge_Scores or Settings and everything updates.

Sheet Settings
A1: Settings & assumptions
A2: Yellow cells with blue text are inputs — change them and every sheet recalculates.
A4: Setting | B4: Value | C4: Note / source
A5: Show / reference year | B5: 2026 | C5: Used to compute age from BirthYear. Assumed current season.
A6: Max score per trait | B6: 20 | C6: AHA-style halter category maximum (from dataset README).
A7: Max total per judge | B7: 120 | C7: 6 categories x 20 points (from dataset README).
A8: Elite tier — minimum avg total | B8: 112 | C8: Tier cut-offs carried over from the source workbook formulas.
A9: High tier — minimum avg total | B9: 106
A10: Developing tier — minimum avg total | B10: 100 | C10: Below this = "Needs Review".
A11: Colt/Filly maximum age | B11: 3 | C11: Halter convention: colt/filly under 4, stallion/mare 4+. Used for data-quality flag.

Sheet Horse_Profile
A1: HorseID | B1: RegisteredName | C1: BarnName | D1: Sex | E1: BirthYear | F1: AgeGroup | G1: Color | H1: CountryOfFoaling | I1: Sire | J1: Dam | K1: DamSire | L1: PaternalLine | M1: DamLine | N1: FarmGroup | O1: Notes | P1: Age | Q1: DataFlag
A2: HA-001 | B2: HA Amira Legacy | C2: Amira | D2: Gelding | E2: 2023 | F2: Young Horse | G2: Bay | H2: Spain | I2: Pogrom | J2: Rose Amar HA | K2: El Nabila B | L2: Polish/International | M2: Egyptian-influenced | N2: Performance Prospect | O2: Good movement | P2: =Settings!$B$5-E2 -> 3 | Q2: =IF(AND(OR(D2="Colt",D2="Filly"),P2>Settings!$B$11),"Sex/age mismatch",IF(AND(OR(D2="Stallion",D2="Mare"),P2<=Settings!$B$11),"Sex/age mismatch",""))
A3: HA-002 | B3: HA Basir Royal Flame | C3: Basir | D3: Colt | E3: 2024 | F3: Junior | G3: Grey | H3: USA | I3: Pogrom | J3: Sultana Mirage HA | K3: Marwan Al Shaqab | L3: Polish/International | M3: Crabbet-influenced | N3: Breeding Prospect | O3: Good movement | P3: =Settings!$B$5-E3 -> 2 | Q3: =IF(AND(OR(D3="Colt",D3="Filly"),P3>Settings!$B$11),"Sex/age mismatch",IF(AND(OR(D3="Stallion",D3="Mare"),P3<=Settings!$B$11),"Sex/age mismatch",""))
A4: HA-003 | B4: HA Nadir Sundance | C4: Nadir | D4: Stallion | E4: 2024 | F4: Junior | G4: Black | H4: Qatar | I4: Abha Qatar | J4: Amira Star AM | K4: Da Valentino | L4: Qatari/Spanish | M4: Spanish | N4: Youth/Amateur | O4: Strong head and neck | P4: =Settings!$B$5-E4 -> 2 | Q4: =IF(AND(OR(D4="Colt",D4="Filly"),P4>Settings!$B$11),"Sex/age mismatch",IF(AND(OR(D4="Stallion",D4="Mare"),P4<=Settings!$B$11),"Sex/age mismatch","")) -> Sex/age mismatch
A5: HA-004 | B5: HA Layla Dream | C5: Layla | D5: Mare | E5: 2023 | F5: Young Horse | G5: Chestnut | H5: Qatar | I5: Cavali by Da Valentio | J5: Noura Mirage AS | K5: Bey Shah | L5: Valentino/International | M5: Domestic | N5: Youth/Amateur | O5: Scope for conditioning | P5: =Settings!$B$5-E5 -> 3 | Q5: =IF(AND(OR(D5="Colt",D5="Filly"),P5>Settings!$B$11),"Sex/age mismatch",IF(AND(OR(D5="Stallion",D5="Mare"),P5<=Settings!$B$11),"Sex/age mismatch","")) -> Sex/age mismatch
A6: HA-005 | B6: HA Zafir Golden Star | C6: Zafir | D6: Stallion | E6: 2023 | F6: Young Horse | G6: Bay | H6: Poland | I6: Van Gogh AM | J6: Jewel Hammad AM | K6: El Nabila B | L6: Brazilian/International | M6: Spanish | N6: Show String | O6: Strong head and neck | P6: =Settings!$B$5-E6 -> 3 | Q6: =IF(AND(OR(D6="Colt",D6="Filly"),P6>Settings!$B$11),"Sex/age mismatch",IF(AND(OR(D6="Stallion",D6="Mare"),P6<=Settings!$B$11),"Sex/age mismatch","")) -> Sex/age mismatch
A7: HA-006 | B7: HA Malika Amethyst | C7: Malika | D7: Gelding | E7: 2021 | F7: Mature | G7: Black | H7: Poland | I7: Van Gogh AM | J7: Desert Star AS | K7: Gazal Al Shaqab | L7: Brazilian/International | M7: Polish | N7: Breeding Prospect | O7: Scope for conditioning | P7: =Settings!$B$5-E7 -> 5 | Q7: =IF(AND(OR(D7="Colt",D7="Filly"),P7>Settings!$B$11),"Sex/age mismatch",IF(AND(OR(D7="Stallion",D7="Mare"),P7<=Settings!$B$11),"Sex/age mismatch",""))
A8: HA-007 | B8: HA Sultan Golden Star | C8: Sultan | D8: Gelding | E8: 2023 | F8: Young Horse | G8: Black | H8: USA | I8: Titan AS | J8: Sultana Noor AM | K8: WH Justice | L8: American/International | M8: Polish | N8: Performance Prospect | O8: Needs maturity | P8: =Settings!$B$5-E8 -> 3 | Q8: =IF(AND(OR(D8="Colt",D8="Filly"),P8>Settings!$B$11),"Sex/age mismatch",IF(AND(OR(D8="Stallion",D8="Mare"),P8<=Settings!$B$11),"Sex/age mismatch",""))
A9: HA-008 | B9: HA Noor Mirage | C9: Noor | D9: Mare | E9: 2024 | F9: Junior | G9: Chestnut | H9: Poland | I9: Abha Qatar | J9: Belle Noor HA | K9: El Nabila B | L9: Qatari/Spanish | M9: Domestic | N9: Performance Prospect | O9: Needs maturity | P9: =Settings!$B$5-E9 -> 2 | Q9: =IF(AND(OR(D9="Colt",D9="Filly"),P9>Settings!$B$11),"Sex/age mismatch",IF(AND(OR(D9="Stallion",D9="Mare"),P9<=Settings!$B$11),"Sex/age mismatch","")) -> Sex/age mismatch
A10: HA-009 | B10: HA Rayan Dream | C10: Rayan | D10: Colt | E10: 2024 | F10: Junior | G10: Bay | H10: USA | I10: Pogrom | J10: Lady Amar AM | K10: Versace | L10: Polish/International | M10: Egyptian-influenced | N10: Youth/Amateur | O10: Needs maturity | P10: =Settings!$B$5-E10 -> 2 | Q10: =IF(AND(OR(D10="Colt",D10="Filly"),P10>Settings!$B$11),"Sex/age mismatch",IF(AND(OR(D10="Stallion",D10="Mare"),P10<=Settings!$B$11),"Sex/age mismatch",""))
A11: HA-010 | B11: HA Sahara Desert Rose | C11: Sahara | D11: Mare | E11: 2024 | F11: Junior | G11: Flea-bitten Grey | H11: Poland | I11: Titan AS | J11: Amira Amar AS | K11: Ali Jamaal | L11: American/International | M11: Egyptian-influenced | N11: Youth/Amateur | O11: Scope for conditioning | P11: =Settings!$B$5-E11 -> 2 | Q11: =IF(AND(OR(D11="Colt",D11="Filly"),P11>Settings!$B$11),"Sex/age mismatch",IF(AND(OR(D11="Stallion",D11="Mare"),P11<=Settings!$B$11),"Sex/age mismatch","")) -> Sex/age mismatch
A12: HA-011 | B12: HA Amani Moonlight | C12: Amani | D12: Stallion | E12: 2020 | F12: Mature | G12: Chestnut | H12: USA | I12: Van Gogh AM | J12: Noura Amar HA | K12: Padron | L12: Brazilian/International | M12: Spanish | N12: Foundation Mare | O12: Balanced profile | P12: =Settings!$B$5-E12 -> 6 | Q12: =IF(AND(OR(D12="Colt",D12="Filly"),P12>Settings!$B$11),"Sex/age mismatch",IF(AND(OR(D12="Stallion",D12="Mare"),P12<=Settings!$B$11),"Sex/age mismatch",""))
A13: HA-012 | B13: HA Kareem Amethyst | C13: Kareem | D13: Gelding | E13: 2024 | F13: Junior | G13: Grey | H13: Brazil | I13: Titan AS | J13: Jewel Hammad AS | K13: Padron | L13: American/International | M13: Egyptian-influenced | N13: Show String | O13: Scope for conditioning | P13: =Settings!$B$5-E13 -> 2 | Q13: =IF(AND(OR(D13="Colt",D13="Filly"),P13>Settings!$B$11),"Sex/age mismatch",IF(AND(OR(D13="Stallion",D13="Mare"),P13<=Settings!$B$11),"Sex/age mismatch",""))
... A41: HA-040 | B41: HA Kairo Marquis | C41: Kairo | D41: Filly | E41: 2023 | F41: Young Horse | G41: Black | H41: USA | I41: Pogrom | J41: Belle Rose AM | K41: El Nabila B | L41: Polish/International | M41: International | N41: Show String | O41: Good movement | P41: =Settings!$B$5-E41 -> 3 | Q41: =IF(AND(OR(D41="Colt",D41="Filly"),P41>Settings!$B$11),"Sex/age mismatch",IF(AND(OR(D41="Stallion",D41="Mare"),P41<=Settings!$B$11),"Sex/age mismatch",""))

Sheet Judge_Scores
A1: ScoreID | B1: HorseID | C1: RegisteredName | D1: Judge | E1: Type | F1: Head_Neck | G1: Body_Topline | H1: Legs | I1: Movement | J1: Balance | K1: TotalScore | L1: JudgeComments
A2: SC-0001 | B2: HA-001 | C2: HA Amira Legacy | D2: Judge A | E2: 19.9 | F2: 20 | G2: 18.5 | H2: 18.1 | I2: 18.2 | J2: 19.8 | K2: =SUM(E2:J2) -> 114.5 | L2: Solid score pattern; useful for bloodline comparison.
A3: SC-0002 | B3: HA-001 | C3: HA Amira Legacy | D3: Judge B | E3: 17 | F3: 19 | G3: 19.2 | H3: 17.9 | I3: 20 | J3: 19.6 | K3: =SUM(E3:J3) -> 112.7 | L3: Shows promise across multiple halter traits.
A4: SC-0003 | B4: HA-001 | C4: HA Amira Legacy | D4: Judge C | E4: 18.7 | F4: 18.1 | G4: 19.6 | H4: 18.1 | I4: 18.6 | J4: 20 | K4: =SUM(E4:J4) -> 113.1 | L4: Good quality; monitor consistency across traits.
A5: SC-0004 | B5: HA-002 | C5: HA Basir Royal Flame | D5: Judge A | E5: 19.9 | F5: 18.5 | G5: 19.8 | H5: 19 | I5: 19.1 | J5: 17.7 | K5: =SUM(E5:J5) -> 114 | L5: Strong presence with balanced strengths.
A6: SC-0005 | B6: HA-002 | C6: HA Basir Royal Flame | D6: Judge B | E6: 20 | F6: 16.9 | G6: 19 | H6: 20 | I6: 17.2 | J6: 18 | K6: =SUM(E6:J6) -> 111.1 | L6: Attractive profile and useful movement.
A7: SC-0006 | B7: HA-002 | C7: HA Basir Royal Flame | D7: Judge C | E7: 17.2 | F7: 15.3 | G7: 19.6 | H7: 17.1 | I7: 19.5 | J7: 17.3 | K7: =SUM(E7:J7) -> 106 | L7: Attractive profile and useful movement.
A8: SC-0007 | B8: HA-003 | C8: HA Nadir Sundance | D8: Judge A | E8: 16.4 | F8: 19.2 | G8: 17.9 | H8: 16.4 | I8: 17.9 | J8: 17.1 | K8: =SUM(E8:J8) -> 104.9 | L8: Strong presence with balanced strengths.
A9: SC-0008 | B9: HA-003 | C9: HA Nadir Sundance | D9: Judge B | E9: 18.4 | F9: 18.9 | G9: 18.4 | H9: 17.9 | I9: 17.9 | J9: 18.8 | K9: =SUM(E9:J9) -> 110.3 | L9: Shows promise across multiple halter traits.
A10: SC-0009 | B10: HA-003 | C10: HA Nadir Sundance | D10: Judge C | E10: 20 | F10: 18.5 | G10: 18.1 | H10: 16.8 | I10: 18.2 | J10: 16.4 | K10: =SUM(E10:J10) -> 108 | L10: Good quality; monitor consistency across traits.
A11: SC-0010 | B11: HA-004 | C11: HA Layla Dream | D11: Judge A | E11: 18.4 | F11: 19 | G11: 17.5 | H11: 18.5 | I11: 18.1 | J11: 17.5 | K11: =SUM(E11:J11) -> 109 | L11: Shows promise across multiple halter traits.
A12: SC-0011 | B12: HA-004 | C12: HA Layla Dream | D12: Judge B | E12: 19.6 | F12: 19.7 | G12: 19.3 | H12: 19.3 | I12: 19.8 | J12: 19.1 | K12: =SUM(E12:J12) -> 116.8 | L12: Solid score pattern; useful for bloodline comparison.
A13: SC-0012 | B13: HA-004 | C13: HA Layla Dream | D13: Judge C | E13: 18.6 | F13: 18.2 | G13: 16.3 | H13: 19 | I13: 19 | J13: 19.5 | K13: =SUM(E13:J13) -> 110.6 | L13: Nice outline with room for development.
... A121: SC-0120 | B121: HA-040 | C121: HA Kairo Marquis | D121: Judge C | E121: 18.8 | F121: 16.8 | G121: 17.5 | H121: 18.2 | I121: 20 | J121: 18.8 | K121: =SUM(E121:J121) -> 110.1 | L121: Attractive profile and useful movement.

Sheet Parent_Reference
A1: ParentName | B1: ParentType | C1: PrimaryBloodline | D1: HypotheticalShowScore | E1: TypeInfluence | F1: MovementInfluence | G1: Notes | H1: Offspring | I1: OffspringAvg | J1: OffspringVsParent
A2: Pogrom | B2: Sire | C2: Polish/International | D2: 112.7 | E2: Very Strong | F2: Strong | G2: Provided sire name; other score fields are synthetic for practice. | H2: =IF(B2="Sire",COUNTIF(Horse_Summary!$C$2:$C$41,A2),COUNTIF(Horse_Summary!$D$2:$D$41,A2)) -> 10 | I2: =IFERROR(IF(B2="Sire",AVERAGEIF(Horse_Summary!$C$2:$C$41,A2,Horse_Summary!$O$2:$O$41),AVERAGEIF(Horse_Summary!$D$2:$D$41,A2,Horse_Summary!$O$2:$O$41)),"") -> 112.30667 | J2: =IFERROR(I2-D2,"") -> -0.39333333
A3: Abha Qatar | B3: Sire | C3: Qatari/Spanish | D3: 112.9 | E3: Strong | F3: Moderate | G3: Provided sire name; other score fields are synthetic for practice. | H3: =IF(B3="Sire",COUNTIF(Horse_Summary!$C$2:$C$41,A3),COUNTIF(Horse_Summary!$D$2:$D$41,A3)) -> 8 | I3: =IFERROR(IF(B3="Sire",AVERAGEIF(Horse_Summary!$C$2:$C$41,A3,Horse_Summary!$O$2:$O$41),AVERAGEIF(Horse_Summary!$D$2:$D$41,A3,Horse_Summary!$O$2:$O$41)),"") -> 108.95417 | J3: =IFERROR(I3-D3,"") -> -3.9458333
A4: Van Gogh AM | B4: Sire | C4: Brazilian/International | D4: 111.7 | E4: Moderate | F4: Moderate | G4: Provided sire name; other score fields are synthetic for practice. | H4: =IF(B4="Sire",COUNTIF(Horse_Summary!$C$2:$C$41,A4),COUNTIF(Horse_Summary!$D$2:$D$41,A4)) -> 8 | I4: =IFERROR(IF(B4="Sire",AVERAGEIF(Horse_Summary!$C$2:$C$41,A4,Horse_Summary!$O$2:$O$41),AVERAGEIF(Horse_Summary!$D$2:$D$41,A4,Horse_Summary!$O$2:$O$41)),"") -> 108.90417 | J4: =IFERROR(I4-D4,"") -> -2.7958333
A5: Titan AS | B5: Sire | C5: American/International | D5: 111.3 | E5: Moderate | F5: Strong | G5: Provided sire name; other score fields are synthetic for practice. | H5: =IF(B5="Sire",COUNTIF(Horse_Summary!$C$2:$C$41,A5),COUNTIF(Horse_Summary!$D$2:$D$41,A5)) -> 7 | I5: =IFERROR(IF(B5="Sire",AVERAGEIF(Horse_Summary!$C$2:$C$41,A5,Horse_Summary!$O$2:$O$41),AVERAGEIF(Horse_Summary!$D$2:$D$41,A5,Horse_Summary!$O$2:$O$41)),"") -> 106.10476 | J5: =IFERROR(I5-D5,"") -> -5.1952381
A6: Cavali by Da Valentio | B6: Sire | C6: Valentino/International | D6: 112.8 | E6: Very Strong | F6: Very Strong | G6: Provided sire name; other score fields are synthetic for practice. | H6: =IF(B6="Sire",COUNTIF(Horse_Summary!$C$2:$C$41,A6),COUNTIF(Horse_Summary!$D$2:$D$41,A6)) -> 7 | I6: =IFERROR(IF(B6="Sire",AVERAGEIF(Horse_Summary!$C$2:$C$41,A6,Horse_Summary!$O$2:$O$41),AVERAGEIF(Horse_Summary!$D$2:$D$41,A6,Horse_Summary!$O$2:$O$41)),"") -> 112.14762 | J6: =IFERROR(I6-D6,"") -> -0.65238095
A7: Ali Jamaal | B7: Dam Sire | C7: Spanish | D7: 109.7 | E7: Very Strong | F7: Strong | G7: Synthetic supporting pedigree field for practice. | H7: =IF(B7="Sire",COUNTIF(Horse_Summary!$C$2:$C$41,A7),COUNTIF(Horse_Summary!$D$2:$D$41,A7)) -> 4 | I7: =IFERROR(IF(B7="Sire",AVERAGEIF(Horse_Summary!$C$2:$C$41,A7,Horse_Summary!$O$2:$O$41),AVERAGEIF(Horse_Summary!$D$2:$D$41,A7,Horse_Summary!$O$2:$O$41)),"") -> 108.7 | J7: =IFERROR(I7-D7,"") -> -1
A8: Bey Shah | B8: Dam Sire | C8: Spanish | D8: 111.5 | E8: Moderate | F8: Moderate | G8: Synthetic supporting pedigree field for practice. | H8: =IF(B8="Sire",COUNTIF(Horse_Summary!$C$2:$C$41,A8),COUNTIF(Horse_Summary!$D$2:$D$41,A8)) -> 4 | I8: =IFERROR(IF(B8="Sire",AVERAGEIF(Horse_Summary!$C$2:$C$41,A8,Horse_Summary!$O$2:$O$41),AVERAGEIF(Horse_Summary!$D$2:$D$41,A8,Horse_Summary!$O$2:$O$41)),"") -> 111.79167 | J8: =IFERROR(I8-D8,"") -> 0.29166667
A9: Da Valentino | B9: Dam Sire | C9: American | D9: 106.8 | E9: Strong | F9: Moderate | G9: Synthetic supporting pedigree field for practice. | H9: =IF(B9="Sire",COUNTIF(Horse_Summary!$C$2:$C$41,A9),COUNTIF(Horse_Summary!$D$2:$D$41,A9)) -> 1 | I9: =IFERROR(IF(B9="Sire",AVERAGEIF(Horse_Summary!$C$2:$C$41,A9,Horse_Summary!$O$2:$O$41),AVERAGEIF(Horse_Summary!$D$2:$D$41,A9,Horse_Summary!$O$2:$O$41)),"") -> 107.73333 | J9: =IFERROR(I9-D9,"") -> 0.93333333
A10: El Nabila B | B10: Dam Sire | C10: Spanish | D10: 106.5 | E10: Moderate | F10: Moderate | G10: Synthetic supporting pedigree field for practice. | H10: =IF(B10="Sire",COUNTIF(Horse_Summary!$C$2:$C$41,A10),COUNTIF(Horse_Summary!$D$2:$D$41,A10)) -> 8 | I10: =IFERROR(IF(B10="Sire",AVERAGEIF(Horse_Summary!$C$2:$C$41,A10,Horse_Summary!$O$2:$O$41),AVERAGEIF(Horse_Summary!$D$2:$D$41,A10,Horse_Summary!$O$2:$O$41)),"") -> 109.61667 | J10: =IFERROR(I10-D10,"") -> 3.1166667
A11: Gazal Al Shaqab | B11: Dam Sire | C11: International | D11: 107.6 | E11: Strong | F11: Strong | G11: Synthetic supporting pedigree field for practice. | H11: =IF(B11="Sire",COUNTIF(Horse_Summary!$C$2:$C$41,A11),COUNTIF(Horse_Summary!$D$2:$D$41,A11)) -> 6 | I11: =IFERROR(IF(B11="Sire",AVERAGEIF(Horse_Summary!$C$2:$C$41,A11,Horse_Summary!$O$2:$O$41),AVERAGEIF(Horse_Summary!$D$2:$D$41,A11,Horse_Summary!$O$2:$O$41)),"") -> 111.37222 | J11: =IFERROR(I11-D11,"") -> 3.7722222
A12: Magnum Psyche | B12: Dam Sire | C12: Polish | D12: 106.5 | E12: Strong | F12: Moderate | G12: Synthetic supporting pedigree field for practice. | H12: =IF(B12="Sire",COUNTIF(Horse_Summary!$C$2:$C$41,A12),COUNTIF(Horse_Summary!$D$2:$D$41,A12)) -> 4 | I12: =IFERROR(IF(B12="Sire",AVERAGEIF(Horse_Summary!$C$2:$C$41,A12,Horse_Summary!$O$2:$O$41),AVERAGEIF(Horse_Summary!$D$2:$D$41,A12,Horse_Summary!$O$2:$O$41)),"") -> 110.25 | J12: =IFERROR(I12-D12,"") -> 3.75
A13: Marwan Al Shaqab | B13: Dam Sire | C13: Egyptian | D13: 107.2 | E13: Strong | F13: Moderate | G13: Synthetic supporting pedigree field for practice. | H13: =IF(B13="Sire",COUNTIF(Horse_Summary!$C$2:$C$41,A13),COUNTIF(Horse_Summary!$D$2:$D$41,A13)) -> 2 | I13: =IFERROR(IF(B13="Sire",AVERAGEIF(Horse_Summary!$C$2:$C$41,A13,Horse_Summary!$O$2:$O$41),AVERAGEIF(Horse_Summary!$D$2:$D$41,A13,Horse_Summary!$O$2:$O$41)),"") -> 111.05 | J13: =IFERROR(I13-D13,"") -> 3.85
... A16: WH Justice | B16: Dam Sire | C16: Spanish | D16: 104.6 | E16: Moderate | F16: Moderate | G16: Synthetic supporting pedigree field for practice. | H16: =IF(B16="Sire",COUNTIF(Horse_Summary!$C$2:$C$41,A16),COUNTIF(Horse_Summary!$D$2:$D$41,A16)) -> 1 | I16: =IFERROR(IF(B16="Sire",AVERAGEIF(Horse_Summary!$C$2:$C$41,A16,Horse_Summary!$O$2:$O$41),AVERAGEIF(Horse_Summary!$D$2:$D$41,A16,Horse_Summary!$O$2:$O$41)),"") -> 103.46667 | J16: =IFERROR(I16-D16,"") -> -1.1333333

Sheet Horse_Summary
A1: HorseID | B1: RegisteredName | C1: Sire | D1: DamSire | E1: Sex | F1: AgeGroup | G1: PaternalLine | H1: DamLine | I1: Type | J1: Head_Neck | K1: Body_Topline | L1: Legs | M1: Movement | N1: Balance | O1: AvgTotal | P1: JudgeSpread | Q1: Rank | R1: UniqueRank | S1: ScoreTier | T1: MainStrength | U1: FocusArea | V1: SireScore | W1: DamSireScore | X1: MidParentScore | Y1: RankInSireLine | Z1: SireKey | AA1: VsSireScore | AB1: DataFlag
A2: HA-001 | B2: =INDEX(Horse_Profile!$B$2:$B$41,MATCH($A2,Horse_Profile!$A$2:$A$41,0)) -> HA Amira Legacy | C2: =INDEX(Horse_Profile!$I$2:$I$41,MATCH($A2,Horse_Profile!$A$2:$A$41,0)) -> Pogrom | D2: =INDEX(Horse_Profile!$K$2:$K$41,MATCH($A2,Horse_Profile!$A$2:$A$41,0)) -> El Nabila B | E2: =INDEX(Horse_Profile!$D$2:$D$41,MATCH($A2,Horse_Profile!$A$2:$A$41,0)) -> Gelding | F2: =INDEX(Horse_Profile!$F$2:$F$41,MATCH($A2,Horse_Profile!$A$2:$A$41,0)) -> Young Horse | G2: =INDEX(Horse_Profile!$L$2:$L$41,MATCH($A2,Horse_Profile!$A$2:$A$41,0)) -> Polish/International | H2: =INDEX(Horse_Profile!$M$2:$M$41,MATCH($A2,Horse_Profile!$A$2:$A$41,0)) -> Egyptian-influenced | I2: =AVERAGEIF(Judge_Scores!$B$2:$B$121,$A2,Judge_Scores!$E$2:$E$121) -> 18.533333 | J2: =AVERAGEIF(Judge_Scores!$B$2:$B$121,$A2,Judge_Scores!$F$2:$F$121) -> 19.033333 | K2: =AVERAGEIF(Judge_Scores!$B$2:$B$121,$A2,Judge_Scores!$G$2:$G$121) -> 19.1 | L2: =AVERAGEIF(Judge_Scores!$B$2:$B$121,$A2,Judge_Scores!$H$2:$H$121) -> 18.033333 | M2: =AVERAGEIF(Judge_Scores!$B$2:$B$121,$A2,Judge_Scores!$I$2:$I$121) -> 18.933333 | N2: =AVERAGEIF(Judge_Scores!$B$2:$B$121,$A2,Judge_Scores!$J$2:$J$121) -> 19.8 | O2: =AVERAGEIF(Judge_Scores!$B$2:$B$121,$A2,Judge_Scores!$K$2:$K$121) -> 113.43333 | P2: =_xlfn.MAXIFS(Judge_Scores!$K$2:$K$121,Judge_Scores!$B$2:$B$121,$A2)-_xlfn.MINIFS(Judge_Scores!$K$2:$K$121,Judge_Scores!$B$2:$B$121,$A2) -> 1.8 | Q2: =RANK(O2,$O$2:$O$41,0) -> 4 | R2: =Q2+COUNTIF($O$2:O2,O2)-1 -> 4 | S2: =IF(O2>=Settings!$B$8,"Elite",IF(O2>=Settings!$B$9,"High",IF(O2>=Settings!$B$10,"Developing","Needs Review"))) -> Elite | T2: =INDEX($I$1:$N$1,MATCH(MAX(I2:N2),I2:N2,0)) -> Balance | U2: =INDEX($I$1:$N$1,MATCH(MIN(I2:N2),I2:N2,0)) -> Legs | V2: =INDEX(Parent_Reference!$D$2:$D$16,MATCH(C2,Parent_Reference!$A$2:$A$16,0)) -> 112.7 | W2: =INDEX(Parent_Reference!$D$2:$D$16,MATCH(D2,Parent_Reference!$A$2:$A$16,0)) -> 106.5 | X2: =AVERAGE(V2:W2) -> 109.6 | Y2: =COUNTIFS($C$2:$C$41,C2,$O$2:$O$41,">"&O2)+1 -> 4 | Z2: =C2&"|"&Y2 -> Pogrom|4 | AA2: =O2-V2 -> 0.73333333 | AB2: =INDEX(Horse_Profile!$Q$2:$Q$41,MATCH($A2,Horse_Profile!$A$2:$A$41,0))
A3: HA-002 | B3: =INDEX(Horse_Profile!$B$2:$B$41,MATCH($A3,Horse_Profile!$A$2:$A$41,0)) -> HA Basir Royal Flame | C3: =INDEX(Horse_Profile!$I$2:$I$41,MATCH($A3,Horse_Profile!$A$2:$A$41,0)) -> Pogrom | D3: =INDEX(Horse_Profile!$K$2:$K$41,MATCH($A3,Horse_Profile!$A$2:$A$41,0)) -> Marwan Al Shaqab | E3: =INDEX(Horse_Profile!$D$2:$D$41,MATCH($A3,Horse_Profile!$A$2:$A$41,0)) -> Colt | F3: =INDEX(Horse_Profile!$F$2:$F$41,MATCH($A3,Horse_Profile!$A$2:$A$41,0)) -> Junior | G3: =INDEX(Horse_Profile!$L$2:$L$41,MATCH($A3,Horse_Profile!$A$2:$A$41,0)) -> Polish/International | H3: =INDEX(Horse_Profile!$M$2:$M$41,MATCH($A3,Horse_Profile!$A$2:$A$41,0)) -> Crabbet-influenced | I3: =AVERAGEIF(Judge_Scores!$B$2:$B$121,$A3,Judge_Scores!$E$2:$E$121) -> 19.033333 | J3: =AVERAGEIF(Judge_Scores!$B$2:$B$121,$A3,Judge_Scores!$F$2:$F$121) -> 16.9 | K3: =AVERAGEIF(Judge_Scores!$B$2:$B$121,$A3,Judge_Scores!$G$2:$G$121) -> 19.466667 | L3: =AVERAGEIF(Judge_Scores!$B$2:$B$121,$A3,Judge_Scores!$H$2:$H$121) -> 18.7 | M3: =AVERAGEIF(Judge_Scores!$B$2:$B$121,$A3,Judge_Scores!$I$2:$I$121) -> 18.6 | N3: =AVERAGEIF(Judge_Scores!$B$2:$B$121,$A3,Judge_Scores!$J$2:$J$121) -> 17.666667 | O3: =AVERAGEIF(Judge_Scores!$B$2:$B$121,$A3,Judge_Scores!$K$2:$K$121) -> 110.36667 | P3: =_xlfn.MAXIFS(Judge_Scores!$K$2:$K$121,Judge_Scores!$B$2:$B$121,$A3)-_xlfn.MINIFS(Judge_Scores!$K$2:$K$121,Judge_Scores!$B$2:$B$121,$A3) -> 8 | Q3: =RANK(O3,$O$2:$O$41,0) -> 22 | R3: =Q3+COUNTIF($O$2:O3,O3)-1 -> 22 | S3: =IF(O3>=Settings!$B$8,"Elite",IF(O3>=Settings!$B$9,"High",IF(O3>=Settings!$B$10,"Developing","Needs Review"))) -> High | T3: =INDEX($I$1:$N$1,MATCH(MAX(I3:N3),I3:N3,0)) -> Body_Topline | U3: =INDEX($I$1:$N$1,MATCH(MIN(I3:N3),I3:N3,0)) -> Head_Neck | V3: =INDEX(Parent_Reference!$D$2:$D$16,MATCH(C3,Parent_Reference!$A$2:$A$16,0)) -> 112.7 | W3: =INDEX(Parent_Reference!$D$2:$D$16,MATCH(D3,Parent_Reference!$A$2:$A$16,0)) -> 107.2 | X3: =AVERAGE(V3:W3) -> 109.95 | Y3: =COUNTIFS($C$2:$C$41,C3,$O$2:$O$41,">"&O3)+1 -> 10 | Z3: =C3&"|"&Y3 -> Pogrom|10 | AA3: =O3-V3 -> -2.3333333 | AB3: =INDEX(Horse_Profile!$Q$2:$Q$41,MATCH($A3,Horse_Profile!$A$2:$A$41,0))
A4: HA-003 | B4: =INDEX(Horse_Profile!$B$2:$B$41,MATCH($A4,Horse_Profile!$A$2:$A$41,0)) -> HA Nadir Sundance | C4: =INDEX(Horse_Profile!$I$2:$I$41,MATCH($A4,Horse_Profile!$A$2:$A$41,0)) -> Abha Qatar | D4: =INDEX(Horse_Profile!$K$2:$K$41,MATCH($A4,Horse_Profile!$A$2:$A$41,0)) -> Da Valentino | E4: =INDEX(Horse_Profile!$D$2:$D$41,MATCH($A4,Horse_Profile!$A$2:$A$41,0)) -> Stallion | F4: =INDEX(Horse_Profile!$F$2:$F$41,MATCH($A4,Horse_Profile!$A$2:$A$41,0)) -> Junior | G4: =INDEX(Horse_Profile!$L$2:$L$41,MATCH($A4,Horse_Profile!$A$2:$A$41,0)) -> Qatari/Spanish | H4: =INDEX(Horse_Profile!$M$2:$M$41,MATCH($A4,Horse_Profile!$A$2:$A$41,0)) -> Spanish | I4: =AVERAGEIF(Judge_Scores!$B$2:$B$121,$A4,Judge_Scores!$E$2:$E$121) -> 18.266667 | J4: =AVERAGEIF(Judge_Scores!$B$2:$B$121,$A4,Judge_Scores!$F$2:$F$121) -> 18.866667 | K4: =AVERAGEIF(Judge_Scores!$B$2:$B$121,$A4,Judge_Scores!$G$2:$G$121) -> 18.133333 | L4: =AVERAGEIF(Judge_Scores!$B$2:$B$121,$A4,Judge_Scores!$H$2:$H$121) -> 17.033333 | M4: =AVERAGEIF(Judge_Scores!$B$2:$B$121,$A4,Judge_Scores!$I$2:$I$121) -> 18 | N4: =AVERAGEIF(Judge_Scores!$B$2:$B$121,$A4,Judge_Scores!$J$2:$J$121) -> 17.433333 | O4: =AVERAGEIF(Judge_Scores!$B$2:$B$121,$A4,Judge_Scores!$K$2:$K$121) -> 107.73333 | P4: =_xlfn.MAXIFS(Judge_Scores!$K$2:$K$121,Judge_Scores!$B$2:$B$121,$A4)-_xlfn.MINIFS(Judge_Scores!$K$2:$K$121,Judge_Scores!$B$2:$B$121,$A4) -> 5.4 | Q4: =RANK(O4,$O$2:$O$41,0) -> 32 | R4: =Q4+COUNTIF($O$2:O4,O4)-1 -> 32 | S4: =IF(O4>=Settings!$B$8,"Elite",IF(O4>=Settings!$B$9,"High",IF(O4>=Settings!$B$10,"Developing","Needs Review"))) -> High | T4: =INDEX($I$1:$N$1,MATCH(MAX(I4:N4),I4:N4,0)) -> Head_Neck | U4: =INDEX($I$1:$N$1,MATCH(MIN(I4:N4),I4:N4,0)) -> Legs | V4: =INDEX(Parent_Reference!$D$2:$D$16,MATCH(C4,Parent_Reference!$A$2:$A$16,0)) -> 112.9 | W4: =INDEX(Parent_Reference!$D$2:$D$16,MATCH(D4,Parent_Reference!$A$2:$A$16,0)) -> 106.8 | X4: =AVERAGE(V4:W4) -> 109.85 | Y4: =COUNTIFS($C$2:$C$41,C4,$O$2:$O$41,">"&O4)+1 -> 6 | Z4: =C4&"|"&Y4 -> Abha Qatar|6 | AA4: =O4-V4 -> -5.1666667 | AB4: =INDEX(Horse_Profile!$Q$2:$Q$41,MATCH($A4,Horse_Profile!$A$2:$A$41,0)) -> Sex/age mismatch
A5: HA-004 | B5: =INDEX(Horse_Profile!$B$2:$B$41,MATCH($A5,Horse_Profile!$A$2:$A$41,0)) -> HA Layla Dream | C5: =INDEX(Horse_Profile!$I$2:$I$41,MATCH($A5,Horse_Profile!$A$2:$A$41,0)) -> Cavali by Da Valentio | D5: =INDEX(Horse_Profile!$K$2:$K$41,MATCH($A5,Horse_Profile!$A$2:$A$41,0)) -> Bey Shah | E5: =INDEX(Horse_Profile!$D$2:$D$41,MATCH($A5,Horse_Profile!$A$2:$A$41,0)) -> Mare | F5: =INDEX(Horse_Profile!$F$2:$F$41,MATCH($A5,Horse_Profile!$A$2:$A$41,0)) -> Young Horse | G5: =INDEX(Horse_Profile!$L$2:$L$41,MATCH($A5,Horse_Profile!$A$2:$A$41,0)) -> Valentino/International | H5: =INDEX(Horse_Profile!$M$2:$M$41,MATCH($A5,Horse_Profile!$A$2:$A$41,0)) -> Domestic | I5: =AVERAGEIF(Judge_Scores!$B$2:$B$121,$A5,Judge_Scores!$E$2:$E$121) -> 18.866667 | J5: =AVERAGEIF(Judge_Scores!$B$2:$B$121,$A5,Judge_Scores!$F$2:$F$121) -> 18.966667 | K5: =AVERAGEIF(Judge_Scores!$B$2:$B$121,$A5,Judge_Scores!$G$2:$G$121) -> 17.7 | L5: =AVERAGEIF(Judge_Scores!$B$2:$B$121,$A5,Judge_Scores!$H$2:$H$121) -> 18.933333 | M5: =AVERAGEIF(Judge_Scores!$B$2:$B$121,$A5,Judge_Scores!$I$2:$I$121) -> 18.966667 | N5: =AVERAGEIF(Judge_Scores!$B$2:$B$121,$A5,Judge_Scores!$J$2:$J$121) -> 18.7 | O5: =AVERAGEIF(Judge_Scores!$B$2:$B$121,$A5,Judge_Scores!$K$2:$K$121) -> 112.13333 | P5: =_xlfn.MAXIFS(Judge_Scores!$K$2:$K$121,Judge_Scores!$B$2:$B$121,$A5)-_xlfn.MINIFS(Judge_Scores!$K$2:$K$121,Judge_Scores!$B$2:$B$121,$A5) -> 7.8 | Q5: =RANK(O5,$O$2:$O$41,0) -> 9 | R5: =Q5+COUNTIF($O$2:O5,O5)-1 -> 9 | S5: =IF(O5>=Settings!$B$8,"Elite",IF(O5>=Settings!$B$9,"High",IF(O5>=Settings!$B$10,"Developing","Needs Review"))) -> Elite | T5: =INDEX($I$1:$N$1,MATCH(MAX(I5:N5),I5:N5,0)) -> Head_Neck | U5: =INDEX($I$1:$N$1,MATCH(MIN(I5:N5),I5:N5,0)) -> Body_Topline | V5: =INDEX(Parent_Reference!$D$2:$D$16,MATCH(C5,Parent_Reference!$A$2:$A$16,0)) -> 112.8 | W5: =INDEX(Parent_Reference!$D$2:$D$16,MATCH(D5,Parent_Reference!$A$2:$A$16,0)) -> 111.5 | X5: =AVERAGE(V5:W5) -> 112.15 | Y5: =COUNTIFS($C$2:$C$41,C5,$O$2:$O$41,">"&O5)+1 -> 4 | Z5: =C5&"|"&Y5 -> Cavali by Da Valentio|4 | AA5: =O5-V5 -> -0.66666667 | AB5: =INDEX(Horse_Profile!$Q$2:$Q$41,MATCH($A5,Horse_Profile!$A$2:$A$41,0)) -> Sex/age mismatch
A6: HA-005 | B6: =INDEX(Horse_Profile!$B$2:$B$41,MATCH($A6,Horse_Profile!$A$2:$A$41,0)) -> HA Zafir Golden Star | C6: =INDEX(Horse_Profile!$I$2:$I$41,MATCH($A6,Horse_Profile!$A$2:$A$41,0)) -> Van Gogh AM | D6: =INDEX(Horse_Profile!$K$2:$K$41,MATCH($A6,Horse_Profile!$A$2:$A$41,0)) -> El Nabila B | E6: =INDEX(Horse_Profile!$D$2:$D$41,MATCH($A6,Horse_Profile!$A$2:$A$41,0)) -> Stallion | F6: =INDEX(Horse_Profile!$F$2:$F$41,MATCH($A6,Horse_Profile!$A$2:$A$41,0)) -> Young Horse | G6: =INDEX(Horse_Profile!$L$2:$L$41,MATCH($A6,Horse_Profile!$A$2:$A$41,0)) -> Brazilian/International | H6: =INDEX(Horse_Profile!$M$2:$M$41,MATCH($A6,Horse_Profile!$A$2:$A$41,0)) -> Spanish | I6: =AVERAGEIF(Judge_Scores!$B$2:$B$121,$A6,Judge_Scores!$E$2:$E$121) -> 18.666667 | J6: =AVERAGEIF(Judge_Scores!$B$2:$B$121,$A6,Judge_Scores!$F$2:$F$121) -> 18.2 | K6: =AVERAGEIF(Judge_Scores!$B$2:$B$121,$A6,Judge_Scores!$G$2:$G$121) -> 18.566667 | L6: =AVERAGEIF(Judge_Scores!$B$2:$B$121,$A6,Judge_Scores!$H$2:$H$121) -> 16.833333 | M6: =AVERAGEIF(Judge_Scores!$B$2:$B$121,$A6,Judge_Scores!$I$2:$I$121) -> 18.366667 | N6: =AVERAGEIF(Judge_Scores!$B$2:$B$121,$A6,Judge_Scores!$J$2:$J$121) -> 17.866667 | O6: =AVERAGEIF(Judge_Scores!$B$2:$B$121,$A6,Judge_Scores!$K$2:$K$121) -> 108.5 | P6: =_xlfn.MAXIFS(Judge_Scores!$K$2:$K$121,Judge_Scores!$B$2:$B$121,$A6)-_xlfn.MINIFS(Judge_Scores!$K$2:$K$121,Judge_Scores!$B$2:$B$121,$A6) -> 4.1 | Q6: =RANK(O6,$O$2:$O$41,0) -> 28 | R6: =Q6+COUNTIF($O$2:O6,O6)-1 -> 28 | S6: =IF(O6>=Settings!$B$8,"Elite",IF(O6>=Settings!$B$9,"High",IF(O6>=Settings!$B$10,"Developing","Needs Review"))) -> High | T6: =INDEX($I$1:$N$1,MATCH(MAX(I6:N6),I6:N6,0)) -> Type | U6: =INDEX($I$1:$N$1,MATCH(MIN(I6:N6),I6:N6,0)) -> Legs | V6: =INDEX(Parent_Reference!$D$2:$D$16,MATCH(C6,Parent_Reference!$A$2:$A$16,0)) -> 111.7 | W6: =INDEX(Parent_Reference!$D$2:$D$16,MATCH(D6,Parent_Reference!$A$2:$A$16,0)) -> 106.5 | X6: =AVERAGE(V6:W6) -> 109.1 | Y6: =COUNTIFS($C$2:$C$41,C6,$O$2:$O$41,">"&O6)+1 -> 4 | Z6: =C6&"|"&Y6 -> Van Gogh AM|4 | AA6: =O6-V6 -> -3.2 | AB6: =INDEX(Horse_Profile!$Q$2:$Q$41,MATCH($A6,Horse_Profile!$A$2:$A$41,0)) -> Sex/age mismatch
A7: HA-006 | B7: =INDEX(Horse_Profile!$B$2:$B$41,MATCH($A7,Horse_Profile!$A$2:$A$41,0)) -> HA Malika Amethyst | C7: =INDEX(Horse_Profile!$I$2:$I$41,MATCH($A7,Horse_Profile!$A$2:$A$41,0)) -> Van Gogh AM | D7: =INDEX(Horse_Profile!$K$2:$K$41,MATCH($A7,Horse_Profile!$A$2:$A$41,0)) -> Gazal Al Shaqab | E7: =INDEX(Horse_Profile!$D$2:$D$41,MATCH($A7,Horse_Profile!$A$2:$A$41,0)) -> Gelding | F7: =INDEX(Horse_Profile!$F$2:$F$41,MATCH($A7,Horse_Profile!$A$2:$A$41,0)) -> Mature | G7: =INDEX(Horse_Profile!$L$2:$L$41,MATCH($A7,Horse_Profile!$A$2:$A$41,0)) -> Brazilian/International | H7: =INDEX(Horse_Profile!$M$2:$M$41,MATCH($A7,Horse_Profile!$A$2:$A$41,0)) -> Polish | I7: =AVERAGEIF(Judge_Scores!$B$2:$B$121,$A7,Judge_Scores!$E$2:$E$121) -> 18.4 | J7: =AVERAGEIF(Judge_Scores!$B$2:$B$121,$A7,Judge_Scores!$F$2:$F$121) -> 19.2 | K7: =AVERAGEIF(Judge_Scores!$B$2:$B$121,$A7,Judge_Scores!$G$2:$G$121) -> 18.5 | L7: =AVERAGEIF(Judge_Scores!$B$2:$B$121,$A7,Judge_Scores!$H$2:$H$121) -> 18.5 | M7: =AVERAGEIF(Judge_Scores!$B$2:$B$121,$A7,Judge_Scores!$I$2:$I$121) -> 18.233333 | N7: =AVERAGEIF(Judge_Scores!$B$2:$B$121,$A7,Judge_Scores!$J$2:$J$121) -> 18.6 | O7: =AVERAGEIF(Judge_Scores!$B$2:$B$121,$A7,Judge_Scores!$K$2:$K$121) -> 111.43333 | P7: =_xlfn.MAXIFS(Judge_Scores!$K$2:$K$121,Judge_Scores!$B$2:$B$121,$A7)-_xlfn.MINIFS(Judge_Scores!$K$2:$K$121,Judge_Scores!$B$2:$B$121,$A7) -> 3.5 | Q7: =RANK(O7,$O$2:$O$41,0) -> 13 | R7: =Q7+COUNTIF($O$2:O7,O7)-1 -> 13 | S7: =IF(O7>=Settings!$B$8,"Elite",IF(O7>=Settings!$B$9,"High",IF(O7>=Settings!$B$10,"Developing","Needs Review"))) -> High | T7: =INDEX($I$1:$N$1,MATCH(MAX(I7:N7),I7:N7,0)) -> Head_Neck | U7: =INDEX($I$1:$N$1,MATCH(MIN(I7:N7),I7:N7,0)) -> Movement | V7: =INDEX(Parent_Reference!$D$2:$D$16,MATCH(C7,Parent_Reference!$A$2:$A$16,0)) -> 111.7 | W7: =INDEX(Parent_Reference!$D$2:$D$16,MATCH(D7,Parent_Reference!$A$2:$A$16,0)) -> 107.6 | X7: =AVERAGE(V7:W7) -> 109.65 | Y7: =COUNTIFS($C$2:$C$41,C7,$O$2:$O$41,">"&O7)+1 -> 1 | Z7: =C7&"|"&Y7 -> Van Gogh AM|1 | AA7: =O7-V7 -> -0.26666667 | AB7: =INDEX(Horse_Profile!$Q$2:$Q$41,MATCH($A7,Horse_Profile!$A$2:$A$41,0))
A8: HA-007 | B8: =INDEX(Horse_Profile!$B$2:$B$41,MATCH($A8,Horse_Profile!$A$2:$A$41,0)) -> HA Sultan Golden Star | C8: =INDEX(Horse_Profile!$I$2:$I$41,MATCH($A8,Horse_Profile!$A$2:$A$41,0)) -> Titan AS | D8: =INDEX(Horse_Profile!$K$2:$K$41,MATCH($A8,Horse_Profile!$A$2:$A$41,0)) -> WH Justice | E8: =INDEX(Horse_Profile!$D$2:$D$41,MATCH($A8,Horse_Profile!$A$2:$A$41,0)) -> Gelding | F8: =INDEX(Horse_Profile!$F$2:$F$41,MATCH($A8,Horse_Profile!$A$2:$A$41,0)) -> Young Horse | G8: =INDEX(Horse_Profile!$L$2:$L$41,MATCH($A8,Horse_Profile!$A$2:$A$41,0)) -> American/International | H8: =INDEX(Horse_Profile!$M$2:$M$41,MATCH($A8,Horse_Profile!$A$2:$A$41,0)) -> Polish | I8: =AVERAGEIF(Judge_Scores!$B$2:$B$121,$A8,Judge_Scores!$E$2:$E$121) -> 16.866667 | J8: =AVERAGEIF(Judge_Scores!$B$2:$B$121,$A8,Judge_Scores!$F$2:$F$121) -> 16.066667 | K8: =AVERAGEIF(Judge_Scores!$B$2:$B$121,$A8,Judge_Scores!$G$2:$G$121) -> 18.7 | L8: =AVERAGEIF(Judge_Scores!$B$2:$B$121,$A8,Judge_Scores!$H$2:$H$121) -> 17.533333 | M8: =AVERAGEIF(Judge_Scores!$B$2:$B$121,$A8,Judge_Scores!$I$2:$I$121) -> 17.533333 | N8: =AVERAGEIF(Judge_Scores!$B$2:$B$121,$A8,Judge_Scores!$J$2:$J$121) -> 16.766667 | O8: =AVERAGEIF(Judge_Scores!$B$2:$B$121,$A8,Judge_Scores!$K$2:$K$121) -> 103.46667 | P8: =_xlfn.MAXIFS(Judge_Scores!$K$2:$K$121,Judge_Scores!$B$2:$B$121,$A8)-_xlfn.MINIFS(Judge_Scores!$K$2:$K$121,Judge_Scores!$B$2:$B$121,$A8) -> 8.9 | Q8: =RANK(O8,$O$2:$O$41,0) -> 39 | R8: =Q8+COUNTIF($O$2:O8,O8)-1 -> 39 | S8: =IF(O8>=Settings!$B$8,"Elite",IF(O8>=Settings!$B$9,"High",IF(O8>=Settings!$B$10,"Developing","Needs Review"))) -> Developing | T8: =INDEX($I$1:$N$1,MATCH(MAX(I8:N8),I8:N8,0)) -> Body_Topline | U8: =INDEX($I$1:$N$1,MATCH(MIN(I8:N8),I8:N8,0)) -> Head_Neck | V8: =INDEX(Parent_Reference!$D$2:$D$16,MATCH(C8,Parent_Reference!$A$2:$A$16,0)) -> 111.3 | W8: =INDEX(Parent_Reference!$D$2:$D$16,MATCH(D8,Parent_Reference!$A$2:$A$16,0)) -> 104.6 | X8: =AVERAGE(V8:W8) -> 107.95 | Y8: =COUNTIFS($C$2:$C$41,C8,$O$2:$O$41,">"&O8)+1 -> 6 | Z8: =C8&"|"&Y8 -> Titan AS|6 | AA8: =O8-V8 -> -7.8333333 | AB8: =INDEX(Horse_Profile!$Q$2:$Q$41,MATCH($A8,Horse_Profile!$A$2:$A$41,0))
A9: HA-008 | B9: =INDEX(Horse_Profile!$B$2:$B$41,MATCH($A9,Horse_Profile!$A$2:$A$41,0)) -> HA Noor Mirage | C9: =INDEX(Horse_Profile!$I$2:$I$41,MATCH($A9,Horse_Profile!$A$2:$A$41,0)) -> Abha Qatar | D9: =INDEX(Horse_Profile!$K$2:$K$41,MATCH($A9,Horse_Profile!$A$2:$A$41,0)) -> El Nabila B | E9: =INDEX(Horse_Profile!$D$2:$D$41,MATCH($A9,Horse_Profile!$A$2:$A$41,0)) -> Mare | F9: =INDEX(Horse_Profile!$F$2:$F$41,MATCH($A9,Horse_Profile!$A$2:$A$41,0)) -> Junior | G9: =INDEX(Horse_Profile!$L$2:$L$41,MATCH($A9,Horse_Profile!$A$2:$A$41,0)) -> Qatari/Spanish | H9: =INDEX(Horse_Profile!$M$2:$M$41,MATCH($A9,Horse_Profile!$A$2:$A$41,0)) -> Domestic | I9: =AVERAGEIF(Judge_Scores!$B$2:$B$121,$A9,Judge_Scores!$E$2:$E$121) -> 18.033333 | J9: =AVERAGEIF(Judge_Scores!$B$2:$B$121,$A9,Judge_Scores!$F$2:$F$121) -> 18.666667 | K9: =AVERAGEIF(Judge_Scores!$B$2:$B$121,$A9,Judge_Scores!$G$2:$G$121) -> 16.633333 | L9: =AVERAGEIF(Judge_Scores!$B$2:$B$121,$A9,Judge_Scores!$H$2:$H$121) -> 16.9 | M9: =AVERAGEIF(Judge_Scores!$B$2:$B$121,$A9,Judge_Scores!$I$2:$I$121) -> 17.466667 | N9: =AVERAGEIF(Judge_Scores!$B$2:$B$121,$A9,Judge_Scores!$J$2:$J$121) -> 18.1 | O9: =AVERAGEIF(Judge_Scores!$B$2:$B$121,$A9,Judge_Scores!$K$2:$K$121) -> 105.8 | P9: =_xlfn.MAXIFS(Judge_Scores!$K$2:$K$121,Judge_Scores!$B$2:$B$121,$A9)-_xlfn.MINIFS(Judge_Scores!$K$2:$K$121,Judge_Scores!$B$2:$B$121,$A9) -> 5 | Q9: =RANK(O9,$O$2:$O$41,0) -> 36 | R9: =Q9+COUNTIF($O$2:O9,O9)-1 -> 36 | S9: =IF(O9>=Settings!$B$8,"Elite",IF(O9>=Settings!$B$9,"High",IF(O9>=Settings!$B$10,"Developing","Needs Review"))) -> Developing | T9: =INDEX($I$1:$N$1,MATCH(MAX(I9:N9),I9:N9,0)) -> Head_Neck | U9: =INDEX($I$1:$N$1,MATCH(MIN(I9:N9),I9:N9,0)) -> Body_Topline | V9: =INDEX(Parent_Reference!$D$2:$D$16,MATCH(C9,Parent_Reference!$A$2:$A$16,0)) -> 112.9 | W9: =INDEX(Parent_Reference!$D$2:$D$16,MATCH(D9,Parent_Reference!$A$2:$A$16,0)) -> 106.5 | X9: =AVERAGE(V9:W9) -> 109.7 | Y9: =COUNTIFS($C$2:$C$41,C9,$O$2:$O$41,">"&O9)+1 -> 8 | Z9: =C9&"|"&Y9 -> Abha Qatar|8 | AA9: =O9-V9 -> -7.1 | AB9: =INDEX(Horse_Profile!$Q$2:$Q$41,MATCH($A9,Horse_Profile!$A$2:$A$41,0)) -> Sex/age mismatch
A10: HA-009 | B10: =INDEX(Horse_Profile!$B$2:$B$41,MATCH($A10,Horse_Profile!$A$2:$A$41,0)) -> HA Rayan Dream | C10: =INDEX(Horse_Profile!$I$2:$I$41,MATCH($A10,Horse_Profile!$A$2:$A$41,0)) -> Pogrom | D10: =INDEX(Horse_Profile!$K$2:$K$41,MATCH($A10,Horse_Profile!$A$2:$A$41,0)) -> Versace | E10: =INDEX(Horse_Profile!$D$2:$D$41,MATCH($A10,Horse_Profile!$A$2:$A$41,0)) -> Colt | F10: =INDEX(Horse_Profile!$F$2:$F$41,MATCH($A10,Horse_Profile!$A$2:$A$41,0)) -> Junior | G10: =INDEX(Horse_Profile!$L$2:$L$41,MATCH($A10,Horse_Profile!$A$2:$A$41,0)) -> Polish/International | H10: =INDEX(Horse_Profile!$M$2:$M$41,MATCH($A10,Horse_Profile!$A$2:$A$41,0)) -> Egyptian-influenced | I10: =AVERAGEIF(Judge_Scores!$B$2:$B$121,$A10,Judge_Scores!$E$2:$E$121) -> 19.2 | J10: =AVERAGEIF(Judge_Scores!$B$2:$B$121,$A10,Judge_Scores!$F$2:$F$121) -> 19.233333 | K10: =AVERAGEIF(Judge_Scores!$B$2:$B$121,$A10,Judge_Scores!$G$2:$G$121) -> 19.033333 | L10: =AVERAGEIF(Judge_Scores!$B$2:$B$121,$A10,Judge_Scores!$H$2:$H$121) -> 18.166667 | M10: =AVERAGEIF(Judge_Scores!$B$2:$B$121,$A10,Judge_Scores!$I$2:$I$121) -> 19.933333 | N10: =AVERAGEIF(Judge_Scores!$B$2:$B$121,$A10,Judge_Scores!$J$2:$J$121) -> 18.3 | O10: =AVERAGEIF(Judge_Scores!$B$2:$B$121,$A10,Judge_Scores!$K$2:$K$121) -> 113.86667 | P10: =_xlfn.MAXIFS(Judge_Scores!$K$2:$K$121,Judge_Scores!$B$2:$B$121,$A10)-_xlfn.MINIFS(Judge_Scores!$K$2:$K$121,Judge_Scores!$B$2:$B$121,$A10) -> 5.9 | Q10: =RANK(O10,$O$2:$O$41,0) -> 3 | R10: =Q10+COUNTIF($O$2:O10,O10)-1 -> 3 | S10: =IF(O10>=Settings!$B$8,"Elite",IF(O10>=Settings!$B$9,"High",IF(O10>=Settings!$B$10,"Developing","Needs Review"))) -> Elite | T10: =INDEX($I$1:$N$1,MATCH(MAX(I10:N10),I10:N10,0)) -> Movement | U10: =INDEX($I$1:$N$1,MATCH(MIN(I10:N10),I10:N10,0)) -> Legs | V10: =INDEX(Parent_Reference!$D$2:$D$16,MATCH(C10,Parent_Reference!$A$2:$A$16,0)) -> 112.7 | W10: =INDEX(Parent_Reference!$D$2:$D$16,MATCH(D10,Parent_Reference!$A$2:$A$16,0)) -> 106.3 | X10: =AVERAGE(V10:W10) -> 109.5 | Y10: =COUNTIFS($C$2:$C$41,C10,$O$2:$O$41,">"&O10)+1 -> 3 | Z10: =C10&"|"&Y10 -> Pogrom|3 | AA10: =O10-V10 -> 1.1666667 | AB10: =INDEX(Horse_Profile!$Q$2:$Q$41,MATCH($A10,Horse_Profile!$A$2:$A$41,0))
A11: HA-010 | B11: =INDEX(Horse_Profile!$B$2:$B$41,MATCH($A11,Horse_Profile!$A$2:$A$41,0)) -> HA Sahara Desert Rose | C11: =INDEX(Horse_Profile!$I$2:$I$41,MATCH($A11,Horse_Profile!$A$2:$A$41,0)) -> Titan AS | D11: =INDEX(Horse_Profile!$K$2:$K$41,MATCH($A11,Horse_Profile!$A$2:$A$41,0)) -> Ali Jamaal | E11: =INDEX(Horse_Profile!$D$2:$D$41,MATCH($A11,Horse_Profile!$A$2:$A$41,0)) -> Mare | F11: =INDEX(Horse_Profile!$F$2:$F$41,MATCH($A11,Horse_Profile!$A$2:$A$41,0)) -> Junior | G11: =INDEX(Horse_Profile!$L$2:$L$41,MATCH($A11,Horse_Profile!$A$2:$A$41,0)) -> American/International | H11: =INDEX(Horse_Profile!$M$2:$M$41,MATCH($A11,Horse_Profile!$A$2:$A$41,0)) -> Egyptian-influenced | I11: =AVERAGEIF(Judge_Scores!$B$2:$B$121,$A11,Judge_Scores!$E$2:$E$121) -> 17.533333 | J11: =AVERAGEIF(Judge_Scores!$B$2:$B$121,$A11,Judge_Scores!$F$2:$F$121) -> 16.7 | K11: =AVERAGEIF(Judge_Scores!$B$2:$B$121,$A11,Judge_Scores!$G$2:$G$121) -> 18.2 | L11: =AVERAGEIF(Judge_Scores!$B$2:$B$121,$A11,Judge_Scores!$H$2:$H$121) -> 17.366667 | M11: =AVERAGEIF(Judge_Scores!$B$2:$B$121,$A11,Judge_Scores!$I$2:$I$121) -> 17.266667 | N11: =AVERAGEIF(Judge_Scores!$B$2:$B$121,$A11,Judge_Scores!$J$2:$J$121) -> 17.566667 | O11: =AVERAGEIF(Judge_Scores!$B$2:$B$121,$A11,Judge_Scores!$K$2:$K$121) -> 104.63333 | P11: =_xlfn.MAXIFS(Judge_Scores!$K$2:$K$121,Judge_Scores!$B$2:$B$121,$A11)-_xlfn.MINIFS(Judge_Scores!$K$2:$K$121,Judge_Scores!$B$2:$B$121,$A11) -> 5.5 | Q11: =RANK(O11,$O$2:$O$41,0) -> 37 | R11: =Q11+COUNTIF($O$2:O11,O11)-1 -> 37 | S11: =IF(O11>=Settings!$B$8,"Elite",IF(O11>=Settings!$B$9,"High",IF(O11>=Settings!$B$10,"Developing","Needs Review"))) -> Developing | T11: =INDEX($I$1:$N$1,MATCH(MAX(I11:N11),I11:N11,0)) -> Body_Topline | U11: =INDEX($I$1:$N$1,MATCH(MIN(I11:N11),I11:N11,0)) -> Head_Neck | V11: =INDEX(Parent_Reference!$D$2:$D$16,MATCH(C11,Parent_Reference!$A$2:$A$16,0)) -> 111.3 | W11: =INDEX(Parent_Reference!$D$2:$D$16,MATCH(D11,Parent_Reference!$A$2:$A$16,0)) -> 109.7 | X11: =AVERAGE(V11:W11) -> 110.5 | Y11: =COUNTIFS($C$2:$C$41,C11,$O$2:$O$41,">"&O11)+1 -> 4 | Z11: =C11&"|"&Y11 -> Titan AS|4 | AA11: =O11-V11 -> -6.6666667 | AB11: =INDEX(Horse_Profile!$Q$2:$Q$41,MATCH($A11,Horse_Profile!$A$2:$A$41,0)) -> Sex/age mismatch
A12: HA-011 | B12: =INDEX(Horse_Profile!$B$2:$B$41,MATCH($A12,Horse_Profile!$A$2:$A$41,0)) -> HA Amani Moonlight | C12: =INDEX(Horse_Profile!$I$2:$I$41,MATCH($A12,Horse_Profile!$A$2:$A$41,0)) -> Van Gogh AM | D12: =INDEX(Horse_Profile!$K$2:$K$41,MATCH($A12,Horse_Profile!$A$2:$A$41,0)) -> Padron | E12: =INDEX(Horse_Profile!$D$2:$D$41,MATCH($A12,Horse_Profile!$A$2:$A$41,0)) -> Stallion | F12: =INDEX(Horse_Profile!$F$2:$F$41,MATCH($A12,Horse_Profile!$A$2:$A$41,0)) -> Mature | G12: =INDEX(Horse_Profile!$L$2:$L$41,MATCH($A12,Horse_Profile!$A$2:$A$41,0)) -> Brazilian/International | H12: =INDEX(Horse_Profile!$M$2:$M$41,MATCH($A12,Horse_Profile!$A$2:$A$41,0)) -> Spanish | I12: =AVERAGEIF(Judge_Scores!$B$2:$B$121,$A12,Judge_Scores!$E$2:$E$121) -> 17.533333 | J12: =AVERAGEIF(Judge_Scores!$B$2:$B$121,$A12,Judge_Scores!$F$2:$F$121) -> 18.666667 | K12: =AVERAGEIF(Judge_Scores!$B$2:$B$121,$A12,Judge_Scores!$G$2:$G$121) -> 18.366667 | L12: =AVERAGEIF(Judge_Scores!$B$2:$B$121,$A12,Judge_Scores!$H$2:$H$121) -> 17.866667 | M12: =AVERAGEIF(Judge_Scores!$B$2:$B$121,$A12,Judge_Scores!$I$2:$I$121) -> 18.733333 | N12: =AVERAGEIF(Judge_Scores!$B$2:$B$121,$A12,Judge_Scores!$J$2:$J$121) -> 16.966667 | O12: =AVERAGEIF(Judge_Scores!$B$2:$B$121,$A12,Judge_Scores!$K$2:$K$121) -> 108.13333 | P12: =_xlfn.MAXIFS(Judge_Scores!$K$2:$K$121,Judge_Scores!$B$2:$B$121,$A12)-_xlfn.MINIFS(Judge_Scores!$K$2:$K$121,Judge_Scores!$B$2:$B$121,$A12) -> 4.2 | Q12: =RANK(O12,$O$2:$O$41,0) -> 29 | R12: =Q12+COUNTIF($O$2:O12,O12)-1 -> 29 | S12: =IF(O12>=Settings!$B$8,"Elite",IF(O12>=Settings!$B$9,"High",IF(O12>=Settings!$B$10,"Developing","Needs Review"))) -> High | T12: =INDEX($I$1:$N$1,MATCH(MAX(I12:N12),I12:N12,0)) -> Movement | U12: =INDEX($I$1:$N$1,MATCH(MIN(I12:N12),I12:N12,0)) -> Balance | V12: =INDEX(Parent_Reference!$D$2:$D$16,MATCH(C12,Parent_Reference!$A$2:$A$16,0)) -> 111.7 | W12: =INDEX(Parent_Reference!$D$2:$D$16,MATCH(D12,Parent_Reference!$A$2:$A$16,0)) -> 112 | X12: =AVERAGE(V12:W12) -> 111.85 | Y12: =COUNTIFS($C$2:$C$41,C12,$O$2:$O$41,">"&O12)+1 -> 5 | Z12: =C12&"|"&Y12 -> Van Gogh AM|5 | AA12: =O12-V12 -> -3.5666667 | AB12: =INDEX(Horse_Profile!$Q$2:$Q$41,MATCH($A12,Horse_Profile!$A$2:$A$41,0))
A13: HA-012 | B13: =INDEX(Horse_Profile!$B$2:$B$41,MATCH($A13,Horse_Profile!$A$2:$A$41,0)) -> HA Kareem Amethyst | C13: =INDEX(Horse_Profile!$I$2:$I$41,MATCH($A13,Horse_Profile!$A$2:$A$41,0)) -> Titan AS | D13: =INDEX(Horse_Profile!$K$2:$K$41,MATCH($A13,Horse_Profile!$A$2:$A$41,0)) -> Padron | E13: =INDEX(Horse_Profile!$D$2:$D$41,MATCH($A13,Horse_Profile!$A$2:$A$41,0)) -> Gelding | F13: =INDEX(Horse_Profile!$F$2:$F$41,MATCH($A13,Horse_Profile!$A$2:$A$41,0)) -> Junior | G13: =INDEX(Horse_Profile!$L$2:$L$41,MATCH($A13,Horse_Profile!$A$2:$A$41,0)) -> American/International | H13: =INDEX(Horse_Profile!$M$2:$M$41,MATCH($A13,Horse_Profile!$A$2:$A$41,0)) -> Egyptian-influenced | I13: =AVERAGEIF(Judge_Scores!$B$2:$B$121,$A13,Judge_Scores!$E$2:$E$121) -> 17.733333 | J13: =AVERAGEIF(Judge_Scores!$B$2:$B$121,$A13,Judge_Scores!$F$2:$F$121) -> 16.033333 | K13: =AVERAGEIF(Judge_Scores!$B$2:$B$121,$A13,Judge_Scores!$G$2:$G$121) -> 18 | L13: =AVERAGEIF(Judge_Scores!$B$2:$B$121,$A13,Judge_Scores!$H$2:$H$121) -> 18.3 | M13: =AVERAGEIF(Judge_Scores!$B$2:$B$121,$A13,Judge_Scores!$I$2:$I$121) -> 16.133333 | N13: =AVERAGEIF(Judge_Scores!$B$2:$B$121,$A13,Judge_Scores!$J$2:$J$121) -> 17.266667 | O13: =AVERAGEIF(Judge_Scores!$B$2:$B$121,$A13,Judge_Scores!$K$2:$K$121) -> 103.46667 | P13: =_xlfn.MAXIFS(Judge_Scores!$K$2:$K$121,Judge_Scores!$B$2:$B$121,$A13)-_xlfn.MINIFS(Judge_Scores!$K$2:$K$121,Judge_Scores!$B$2:$B$121,$A13) -> 0.6 | Q13: =RANK(O13,$O$2:$O$41,0) -> 39 | R13: =Q13+COUNTIF($O$2:O13,O13)-1 -> 40 | S13: =IF(O13>=Settings!$B$8,"Elite",IF(O13>=Settings!$B$9,"High",IF(O13>=Settings!$B$10,"Developing","Needs Review"))) -> Developing | T13: =INDEX($I$1:$N$1,MATCH(MAX(I13:N13),I13:N13,0)) -> Legs | U13: =INDEX($I$1:$N$1,MATCH(MIN(I13:N13),I13:N13,0)) -> Head_Neck | V13: =INDEX(Parent_Reference!$D$2:$D$16,MATCH(C13,Parent_Reference!$A$2:$A$16,0)) -> 111.3 | W13: =INDEX(Parent_Reference!$D$2:$D$16,MATCH(D13,Parent_Reference!$A$2:$A$16,0)) -> 112 | X13: =AVERAGE(V13:W13) -> 111.65 | Y13: =COUNTIFS($C$2:$C$41,C13,$O$2:$O$41,">"&O13)+1 -> 6 | Z13: =C13&"|"&Y13 -> Titan AS|6 | AA13: =O13-V13 -> -7.8333333 | AB13: =INDEX(Horse_Profile!$Q$2:$Q$41,MATCH($A13,Horse_Profile!$A$2:$A$41,0))
... A41: HA-040 | B41: =INDEX(Horse_Profile!$B$2:$B$41,MATCH($A41,Horse_Profile!$A$2:$A$41,0)) -> HA Kairo Marquis | C41: =INDEX(Horse_Profile!$I$2:$I$41,MATCH($A41,Horse_Profile!$A$2:$A$41,0)) -> Pogrom | D41: =INDEX(Horse_Profile!$K$2:$K$41,MATCH($A41,Horse_Profile!$A$2:$A$41,0)) -> El Nabila B | E41: =INDEX(Horse_Profile!$D$2:$D$41,MATCH($A41,Horse_Profile!$A$2:$A$41,0)) -> Filly | F41: =INDEX(Horse_Profile!$F$2:$F$41,MATCH($A41,Horse_Profile!$A$2:$A$41,0)) -> Young Horse | G41: =INDEX(Horse_Profile!$L$2:$L$41,MATCH($A41,Horse_Profile!$A$2:$A$41,0)) -> Polish/International | H41: =INDEX(Horse_Profile!$M$2:$M$41,MATCH($A41,Horse_Profile!$A$2:$A$41,0)) -> International | I41: =AVERAGEIF(Judge_Scores!$B$2:$B$121,$A41,Judge_Scores!$E$2:$E$121) -> 19.033333 | J41: =AVERAGEIF(Judge_Scores!$B$2:$B$121,$A41,Judge_Scores!$F$2:$F$121) -> 18.633333 | K41: =AVERAGEIF(Judge_Scores!$B$2:$B$121,$A41,Judge_Scores!$G$2:$G$121) -> 18.966667 | L41: =AVERAGEIF(Judge_Scores!$B$2:$B$121,$A41,Judge_Scores!$H$2:$H$121) -> 19.033333 | M41: =AVERAGEIF(Judge_Scores!$B$2:$B$121,$A41,Judge_Scores!$I$2:$I$121) -> 19.5 | N41: =AVERAGEIF(Judge_Scores!$B$2:$B$121,$A41,Judge_Scores!$J$2:$J$121) -> 18.766667 | O41: =AVERAGEIF(Judge_Scores!$B$2:$B$121,$A41,Judge_Scores!$K$2:$K$121) -> 113.93333 | P41: =_xlfn.MAXIFS(Judge_Scores!$K$2:$K$121,Judge_Scores!$B$2:$B$121,$A41)-_xlfn.MINIFS(Judge_Scores!$K$2:$K$121,Judge_Scores!$B$2:$B$121,$A41) -> 8.3 | Q41: =RANK(O41,$O$2:$O$41,0) -> 2 | R41: =Q41+COUNTIF($O$2:O41,O41)-1 -> 2 | S41: =IF(O41>=Settings!$B$8,"Elite",IF(O41>=Settings!$B$9,"High",IF(O41>=Settings!$B$10,"Developing","Needs Review"))) -> Elite | T41: =INDEX($I$1:$N$1,MATCH(MAX(I41:N41),I41:N41,0)) -> Movement | U41: =INDEX($I$1:$N$1,MATCH(MIN(I41:N41),I41:N41,0)) -> Head_Neck | V41: =INDEX(Parent_Reference!$D$2:$D$16,MATCH(C41,Parent_Reference!$A$2:$A$16,0)) -> 112.7 | W41: =INDEX(Parent_Reference!$D$2:$D$16,MATCH(D41,Parent_Reference!$A$2:$A$16,0)) -> 106.5 | X41: =AVERAGE(V41:W41) -> 109.6 | Y41: =COUNTIFS($C$2:$C$41,C41,$O$2:$O$41,">"&O41)+1 -> 2 | Z41: =C41&"|"&Y41 -> Pogrom|2 | AA41: =O41-V41 -> 1.2333333 | AB41: =INDEX(Horse_Profile!$Q$2:$Q$41,MATCH($A41,Horse_Profile!$A$2:$A$41,0))

Sheet Bloodline_Analysis
A1: Bloodline analysis
A2: Offspring performance by sire line, dam sire, dam line and farm group. All figures are live formulas on Horse_Summary.
A4: 1 · Sire line comparison
A5: Sire | B5: Paternal line | C5: Horses | D5: Avg total | E5: Std dev | F5: Min | G5: Max | H5: Elite horses | I5: Elite % | J5: Sire show score | K5: Offspring vs sire | L5: Top horse | M5: Rank
A6: Pogrom | B6: =INDEX(Parent_Reference!$C$2:$C$16,MATCH(A6,Parent_Reference!$A$2:$A$16,0)) -> Polish/International | C6: =COUNTIF(Horse_Summary!$C$2:$C$41,A6) -> 10 | D6: =AVERAGEIF(Horse_Summary!$C$2:$C$41,A6,Horse_Summary!$O$2:$O$41) -> 112.30667 | E6: =SQRT(SUMPRODUCT((Horse_Summary!$C$2:$C$41=A6)*(Horse_Summary!$O$2:$O$41-D6)^2)/(C6-1)) -> 1.5660598 | F6: =_xlfn.MINIFS(Horse_Summary!$O$2:$O$41,Horse_Summary!$C$2:$C$41,A6) -> 110.36667 | G6: =_xlfn.MAXIFS(Horse_Summary!$O$2:$O$41,Horse_Summary!$C$2:$C$41,A6) -> 114.33333 | H6: =COUNTIFS(Horse_Summary!$C$2:$C$41,A6,Horse_Summary!$S$2:$S$41,"Elite") -> 5 | I6: =H6/C6 -> 0.5 | J6: =INDEX(Parent_Reference!$D$2:$D$16,MATCH(A6,Parent_Reference!$A$2:$A$16,0)) -> 112.7 | K6: =D6-J6 -> -0.39333333 | L6: =INDEX(Horse_Summary!$B$2:$B$41,MATCH(A6&"|1",Horse_Summary!$Z$2:$Z$41,0)) -> HA Rami Royal Flame | M6: =RANK(D6,$D$6:$D$10,0) -> 1
A7: Cavali by Da Valentio | B7: =INDEX(Parent_Reference!$C$2:$C$16,MATCH(A7,Parent_Reference!$A$2:$A$16,0)) -> Valentino/International | C7: =COUNTIF(Horse_Summary!$C$2:$C$41,A7) -> 7 | D7: =AVERAGEIF(Horse_Summary!$C$2:$C$41,A7,Horse_Summary!$O$2:$O$41) -> 112.14762 | E7: =SQRT(SUMPRODUCT((Horse_Summary!$C$2:$C$41=A7)*(Horse_Summary!$O$2:$O$41-D7)^2)/(C7-1)) -> 0.69331654 | F7: =_xlfn.MINIFS(Horse_Summary!$O$2:$O$41,Horse_Summary!$C$2:$C$41,A7) -> 110.73333 | G7: =_xlfn.MAXIFS(Horse_Summary!$O$2:$O$41,Horse_Summary!$C$2:$C$41,A7) -> 112.8 | H7: =COUNTIFS(Horse_Summary!$C$2:$C$41,A7,Horse_Summary!$S$2:$S$41,"Elite") -> 6 | I7: =H7/C7 -> 0.85714286 | J7: =INDEX(Parent_Reference!$D$2:$D$16,MATCH(A7,Parent_Reference!$A$2:$A$16,0)) -> 112.8 | K7: =D7-J7 -> -0.65238095 | L7: =INDEX(Horse_Summary!$B$2:$B$41,MATCH(A7&"|1",Horse_Summary!$Z$2:$Z$41,0)) -> HA Rashid Golden Star | M7: =RANK(D7,$D$6:$D$10,0) -> 2
